Traceback (most recent call last):
  File "c:\users\sllau\appdata\local\pypoetry\cache\virtualenvs\21w44-nz-covid19-vacination-analysis-north-pdjklkmj-py3.9\lib\site-packages\nbclient\client.py", line 627, in _async_poll_for_reply
    msg = await ensure_async(self.kc.shell_channel.get_msg(timeout=new_timeout))
  File "c:\users\sllau\appdata\local\pypoetry\cache\virtualenvs\21w44-nz-covid19-vacination-analysis-north-pdjklkmj-py3.9\lib\site-packages\nbclient\util.py", line 89, in ensure_async
    result = await obj
  File "c:\users\sllau\appdata\local\pypoetry\cache\virtualenvs\21w44-nz-covid19-vacination-analysis-north-pdjklkmj-py3.9\lib\site-packages\jupyter_client\channels.py", line 230, in get_msg
    raise Empty
_queue.Empty

During handling of the above exception, another exception occurred:

Traceback (most recent call last):
  File "c:\users\sllau\appdata\local\pypoetry\cache\virtualenvs\21w44-nz-covid19-vacination-analysis-north-pdjklkmj-py3.9\lib\site-packages\jupyter_cache\executors\utils.py", line 51, in single_nb_execution
    executenb(
  File "c:\users\sllau\appdata\local\pypoetry\cache\virtualenvs\21w44-nz-covid19-vacination-analysis-north-pdjklkmj-py3.9\lib\site-packages\nbclient\client.py", line 1117, in execute
    return NotebookClient(nb=nb, resources=resources, km=km, **kwargs).execute()
  File "c:\users\sllau\appdata\local\pypoetry\cache\virtualenvs\21w44-nz-covid19-vacination-analysis-north-pdjklkmj-py3.9\lib\site-packages\nbclient\util.py", line 78, in wrapped
    return just_run(coro(*args, **kwargs))
  File "c:\users\sllau\appdata\local\pypoetry\cache\virtualenvs\21w44-nz-covid19-vacination-analysis-north-pdjklkmj-py3.9\lib\site-packages\nbclient\util.py", line 57, in just_run
    return loop.run_until_complete(coro)
  File "c:\Users\SLLau\.pyenv\pyenv-win\versions\3.9.7\lib\asyncio\base_events.py", line 642, in run_until_complete
    return future.result()
  File "c:\users\sllau\appdata\local\pypoetry\cache\virtualenvs\21w44-nz-covid19-vacination-analysis-north-pdjklkmj-py3.9\lib\site-packages\nbclient\client.py", line 558, in async_execute
    await self.async_execute_cell(
  File "c:\users\sllau\appdata\local\pypoetry\cache\virtualenvs\21w44-nz-covid19-vacination-analysis-north-pdjklkmj-py3.9\lib\site-packages\nbclient\client.py", line 846, in async_execute_cell
    exec_reply = await self.task_poll_for_reply
  File "c:\users\sllau\appdata\local\pypoetry\cache\virtualenvs\21w44-nz-covid19-vacination-analysis-north-pdjklkmj-py3.9\lib\site-packages\nbclient\client.py", line 651, in _async_poll_for_reply
    await self._async_handle_timeout(timeout, cell)
  File "c:\users\sllau\appdata\local\pypoetry\cache\virtualenvs\21w44-nz-covid19-vacination-analysis-north-pdjklkmj-py3.9\lib\site-packages\nbclient\client.py", line 701, in _async_handle_timeout
    raise CellTimeoutError.error_from_timeout_and_cell(
nbclient.exceptions.CellTimeoutError: A cell timed out while it was being executed, after 30 seconds.
The message was: Cell execution timed out.
Here is a preview of the cell contents:
-------------------
['from IPython.core.display import display, HTML', 'from plotly.offline import init_notebook_mode, plot', 'init_notebook_mode(connected=True)', '', 'import modules']
...
['data.prep_step_2_read_all_uptake_data()', 'data.prep_step_3_generate_report_data()', '', "plot(dv.plot2(data.df_all_weeks_no_gender_age_category), filename = 'figure2.html')", "display(HTML('figure2.html'))"]
-------------------

